Workbook

Sheet Параметры и допущения
A1: Централизованная телефония на Asterisk: центр в московском ЦОД, выносы по городам
A2: Параметры расчёта. Все прочие листы считают от этих значений — меняйте здесь, а не в самом плане.
A4: Показатель | B4: Значение | C4: Откуда взято
A5: ОСНОВАНИЕ | B5: протокол совещания, п. 3 | C5: «Обсудили верхнеуровневую архитектуру, решили строить централизованную на Asterisk с выносами в кластерах. По плану первый этап все за исключением Воронежа, далее Воронеж.» Уточнение: центр размещается в московском ЦОД, на обеих площадках живые узлы; остальные узлы по городам.
A6: Архитектура | B6: центр в ЦОД + выносы | C6: Центр — московский ЦОД: ДВА ЖИВЫХ УЗЛА в разных залах. Оба обслуживают вызовы, московские 80 абонентов поделены поровну и прописаны друг другу резервными. Панель управления FreePBX включена только на ЦОД-1. Выносы — Ростов, Ставрополь, Нижний Новгород, Славянск-на-Кубани, Воронеж — работают узлами того же кластера: локальная регистрация телефонов и свой выход в город, при отказе площадки телефоны уходят в ЦОД.
A7: Стойки в ЦОД | B7: наши, залы независимы | C7: Два узла в ЦОД действительно резервируют друг друга, а не стоят за одним вводом питания. Это условие, без которого схема резервирования не имела бы смысла.
A8: Ждать никого не нужно | B8: да | C8: Площадки наши, адреса известны, стойки в ЦОД наши, SIP-пользователей ВАТС заводим сами, ПО бесплатное, машины на своей виртуализации. Закупок и внешних согласований в плане нет. Практический вывод: если график поедет, причина будет внутренней — не хватило людей, не согласовали окно, не успели с перенумерацией.
A9: Дата начала работ | B9: 46272 | C9: ДОПУЩЕНИЕ. Понедельник. Отсчёт идёт от старта работ, то есть от стадии «проект открыт». Стадии 0–4 воронки плана автоматизации (постановка задачи, оценка, согласование карточки, ВЕ, приказа) в эти 15 недель не входят и идут до них.
A10: Длительность, недель | B10: 16 | C10: Два этапа подряд: 11 недель без Воронежа + 4 недели Воронеж. Этапы последовательны по решению совещания, совмещать нельзя.
A11: Дата завершения работ | B11: 46381 | C11: Дата начала + 15 недель, последний рабочий день
A12: ЭТАП 1 — центр в ЦОД + все выносы, кроме Воронежа | B12: недели 1–12, 810 абонентов | C12: ЦОД-1 40 и ЦОД-2 40, Ростов 352, Ставрополь 74, Нижний Новгород 164, Славянск-на-Кубани 140.
A13: ЭТАП 2 — Воронеж | B13: недели 13–16, 445 абонентов | C13: Воронеж 229, Мясокомбинат 187, Калуга 29.
A14: Ставрополь получает свою АТС | B14: да, задача 8.2 | C14: Раньше его 74 абонента висели на ростовском сервере и зависели от канала до Ростова. Своя АТС даёт им локальную живучесть и попутно делает число узлов нечётным.
A15: Порядок переноса центра | B15: Ростов → ЦОД-1 → +ЦОД-2 | C15: Вся боевая база сейчас на ростовской АТС. Сначала она вводится в кластер как первый узел (задача 4), затем клонируется в ЦОД-1 и роль мастера передаётся туда, затем ЦОД-1 клонируется в ЦОД-2 (задача 5). Ростов после этого — обычный вынос со своими 352 абонентами. Переустановки нет ни на одном шаге, откат — возврат роли на Ростов.
A16: Пилотный вынос | B16: Ставрополь | C16: Порядок ввода выносов: Ставрополь (пилот), затем Нижний Новгород, затем Славянск-на-Кубани. ВАЖНО ПОНИМАТЬ: у Ставрополя нет своей станции — его 74 абонента уже в общей базе, поэтому пилот проверяет кластер, каналы и провижининг, но НЕ проверяет перенос действующей АТС с её гашением. Эта часть процедуры впервые отрабатывается на Нижнем Новгороде (задача 8.1) — её стоит пройти с тем же вниманием, что и пилот.
A17: Оповещение техподдержки | B17: задача 3 | C17: До начала работ согласован порядок: кто и по какому каналу поднимается по тревоге, за какое время и что считается инцидентом. Порядок роздан всем участникам работ — иначе в первую же нештатную ситуацию искать будет некого.
A18: КОМАНДА ПРОЕКТА | B18: четыре человека
A19: Руководитель | B19: Савенко В. | C19: Главный по проекту, указан заказчиком во всех строках плана.
A20: Основной исполнитель | B20: Цеховской В. | C20: Инженер кластера. Задачи 1–9 и 12 — вся работа с кластером, переносом центра и вводом выносов.
A21: Помощник | B21: Кириевская Е. | C21: Задачи 10, 11, 13, 14 — консолидация мелких АТС и перенумерация. Частичная занятость, идут параллельно основным работам.
A22: Развёртывание и адресация | B22: Дулепов А. | C22: Создание клонов, установка и присвоение IP-адресов на площадках. Проставлен исполнителем в соответствующих подзадачах.
A23: Трудозатраты всего, ч-д | B23: 100 | C23: Сумма по задачам, см. лист плана
A24: в том числе инженер кластера | B24: 70 | C24: Задачи 1–7 и 10. Помещается в 15 недель × 5 дней = 75 ч-д одного человека.
A25: в том числе второй исполнитель | B25: 30 | C25: Задачи 8, 9, 11, 12 — консолидация мелких АТС и перенумерация. Работа организационная, идёт параллельно силами второго человека с частичной занятостью. Одним инженером весь объём в срок не выполняется — это ограничение плана, а не оценка.
A26: Внутренняя ставка, ₽/ч-д | B26: 11515 | C26: Из формулы =11515*M4 в файле «План работ ДИТ 2023.xlsx», колонка «Плановая себестоимость внутренних затрат».
A27: Плановая себестоимость внутренних затрат, ₽ без НДС | B27: =B23*B26 -> 1151500 | C27: Трудозатраты × ставка, рассчитывается формулой
A28: Плановая себестоимость внешних затрат, ₽ без НДС | B28: 0 | C28: Всё программное обеспечение бесплатное: MariaDB Galera, Asterisk, FreePBX, OSS PBX End Point Manager. Все узлы — свои виртуальные машины, закупки нет.
A29: Абонентов в периметре | B29: 1255 | C29: Аудит 12 станций, docs/plan/numbering-plan.csv
A30: Станций сейчас | B30: 12 | C30: Там же
A31: Узлов кластера после внедрения | B31: 7 | C31: ЦОД-1 40 и ЦОД-2 40 (оба живые), Ростов 352, Ставрополь 74, Нижний Новгород 164, Славянск-на-Кубани 140, Воронеж 445. Итого 1255 — сходится с аудитом.
A32: Голосов в кворуме | B32: 7 | C32: Семь узлов — число НЕЧЁТНОЕ, поэтому арбитр не нужен вообще. Кластер переживает потерю трёх узлов и остаётся работоспособным при потере московского ЦОД целиком: у городов остаётся 5 голосов из 7.
A33: Арбитр garbd | B33: не нужен | C33: В прежней версии плана Ставрополь оставался на ростовском сервере, узлов было шесть, и чётность приходилось добирать арбитром. Собственная АТС в Ставрополе делает число нечётным — та же виртуальная машина вместо бесполезного голоса несёт 74 абонента.
A34: Кворум в конце этапа 1 | B34: 6 | C34: ВНИМАНИЕ. Без Воронежа узлов шесть — число чётное. Держится недели 11–12, закрывается вводом Воронежа. Если даже две недели такого состояния неприемлемы, на этот период ставится временный арбитр garbd.
A35: Виртуальных машин добавить | B35: 3 | C35: ЦОД-1, ЦОД-2 и Ставрополь. Все — свои мощности, закупки нет. У четырёх остальных площадок машины уже есть.
A36: Размещение ВМ по хостам | B36: проверить | C36: КРИТИЧНО. Узлы обязаны стоять на разных физических хостах: пять ВМ на одном гипервизоре — это не отказоустойчивый кластер, а пять копий одной точки отказа. Проверяется на этапе 1 до ввода второго узла.
A37: Снимки ВМ как резервная копия | B37: нельзя | C37: Откат узла на снимок возвращает его с устаревшим seqno. Такой узел вводится обратно только через prepare-clone.sh --full-resync. Резервные копии снимаются на уровне базы (mysqldump), а не гипервизора.
A38: Оба узла ЦОД — живые | B38: да | C38: ЦОД-2 не пассивная копия: он несёт вызовы наравне с ЦОД-1. Резерв, который никогда не берёт нагрузку, не проверен — поэтому 80 московских абонентов делятся по 40 на зал, и каждый зал прописан другому резервным. Отказ зала проверяется реальным трафиком, а не инструкцией.
A39: Панель управления FreePBX | B39: ровно на одном узле | C39: Живой Asterisk — не второй FreePBX. Две включённые панели пишут в общую базу наперегонки. На ЦОД-2 FreePBX установлен (он клон) и выключен — включается за минуты. Переключение отрабатывается учебно в задаче 8.
A40: Неделя 16 — предновогодняя | B40: 21–25 декабря | C40: ВНИМАНИЕ. На эту неделю приходится завершение перенумерации Воронежа. Люди в отпусках, проверять изменения некому. Либо старт сдвигается на неделю раньше, либо задача 13 переносится на январь.
A42: Что нужно заполнить вручную
...

Sheet План работ
B1: Централизованная телефония на Asterisk: центр в московском ЦОД (два зала), выносы — Ростов, Ставрополь, Нижний Новгород, Славянск-на-Кубани, Воронеж | P1: Сентябрь 2026 | T1: Октябрь 2026 | X1: Ноябрь 2026 | AC1: Декабрь 2026
A2: № | B2: Название задачи | C2: Категория активности | D2: Программа | E2: Заказчик | F2: Плановые сроки начала | G2: Плановые сроки завершения | H2: Фактические/прогнозные сроки завершения | I2: Проблема | J2: Результат | K2: Исполнитель | L2: Статус | M2: ТРЗ, ч/д | N2: Плановая себестоимость внутренних затрат (ТРЗ), руб. без НДС | O2: Плановая себестоимость внешних затрат, руб. без НДС | P2: 07-13 | Q2: 14-20 | R2: 21-27 | S2: 28-04 | T2: 05-11 | U2: 12-18 | V2: 19-25 | W2: 26-01 | X2: 02-08 | Y2: 09-15 | Z2: 16-22 | AA2: 23-29 | AB2: 30-06 | AC2: 07-13 | AD2: 14-20 | AE2: 21-27
B3: ЭТАП 1 — центр в московском ЦОД и все выносы, кроме Воронежа (недели 1–12, 810 абонентов)
A4: 1 | B4: Подготовка: ЦОД, сеть, виртуальные машины, договорённости с операторами | C4: развитие | D4: Инфраструктура | E4: Савенко В. | F4: ='Параметры и допущения'!$B$9+0 -> 46272 | G4: ='Параметры и допущения'!$B$9+11 -> 46283 | H4: =G4 -> 46283 | I4: Площадки не связаны между собой сетью; в ЦОД не выделены машины под центральные узлы; у площадок нет отдельных учётных записей SIP для выхода в город | J4: VPN между ЦОД и всеми городами поднят, RTT измерен, в ЦОД выделены две ВМ в разных стойках, у каждой площадки заведён свой SIP-пользователь ВАТС | K4: Цеховской В. | L4: планируется | M4: 8 | N4: ='Параметры и допущения'!$B$26*M4 -> 92120 | O4: 0
A5: 1.1 | B5: Утвердить единый план нумерации, разослать сотрудникам новые номера | F5: ='Параметры и допущения'!$B$9+0 -> 46272 | G5: ='Параметры и допущения'!$B$9+4 -> 46276 | J5: План нумерации утверждён, уведомления разосланы | K5: Цеховской В. | L5: планируется | M5: 1
A6: 1.2 | B6: Организовать site-to-site VPN: ЦОД — города | F6: ='Параметры и допущения'!$B$9+0 -> 46272 | G6: ='Параметры и допущения'!$B$9+11 -> 46283 | J6: Сеть между ЦОД и всеми площадками работает | K6: Цеховской В. | L6: планируется | M6: 2
A7: 1.3 | B7: Замерить RTT и потери: ЦОД — каждый город и между залами ЦОД | F7: ='Параметры и допущения'!$B$9+7 -> 46279 | G7: ='Параметры и допущения'!$B$9+11 -> 46283 | J7: Замеры выполнены; площадки с RTT выше 50 мс исключены из синхронной репликации | K7: Цеховской В. | L7: планируется | M7: 1
A8: 1.4 | B8: Собрать адресный план на семь узлов | F8: ='Параметры и допущения'!$B$9+0 -> 46272 | G8: ='Параметры и допущения'!$B$9+4 -> 46276 | J8: Адреса всех площадок известны, план зафиксирован | K8: Дулепов А. | L8: планируется | M8: 1
A9: 1.5 | B9: Выделить три ВМ: две в ЦОД (разные стойки) и одну под Ставрополь | F9: ='Параметры и допущения'!$B$9+0 -> 46272 | G9: ='Параметры и допущения'!$B$9+4 -> 46276 | J9: ВМ выделены, узлы разнесены по физическим хостам | K9: Дулепов А. | L9: планируется | M9: 1
A10: 1.6 | B10: Завести SIP-пользователей ВАТС на каждую площадку | F10: ='Параметры и допущения'!$B$9+0 -> 46272 | G10: ='Параметры и допущения'!$B$9+11 -> 46283 | J10: Учётные записи созданы на все площадки, включая Воронеж | K10: Цеховской В. | L10: планируется | M10: 2
A11: 2 | B11: Смена учётных данных и защита периметра | C11: развитие | D11: Инфраструктура | E11: Савенко В. | F11: ='Параметры и допущения'!$B$9+0 -> 46272 | G11: ='Параметры и допущения'!$B$9+11 -> 46283 | H11: =G11 -> 46283 | I11: Учётные данные телефонии не менялись; журнал безопасности Asterisk не ведётся, подбор паролей не отслеживается | J11: Пароли 444 абонентов, транков, AMI и базы данных сменены; включён журнал безопасности и блокировка подбора; восстановление из резервной копии проверено | K11: Цеховской В. | L11: планируется | M11: 10 | N11: ='Параметры и допущения'!$B$26*M11 -> 115150 | O11: 0
A12: 2.1 | B12: Включить журнал безопасности, fail2ban, ограничить доступ к AMI | F12: ='Параметры и допущения'!$B$9+0 -> 46272 | G12: ='Параметры и допущения'!$B$9+4 -> 46276 | J12: Попытки подбора фиксируются и блокируются | K12: Цеховской В. | L12: планируется | M12: 2
A13: 2.2 | B13: Задать порядок идентификации абонентов и перечень кодеков | F13: ='Параметры и допущения'!$B$9+0 -> 46272 | G13: ='Параметры и допущения'!$B$9+4 -> 46276 | J13: Идентификация по учётной записи, alaw первым кодеком | K13: Цеховской В. | L13: планируется | M13: 1
A14: 2.3 | B14: Сменить пароли 444 абонентов | F14: ='Параметры и допущения'!$B$9+0 -> 46272 | G14: ='Параметры и допущения'!$B$9+11 -> 46283 | J14: Пароли сменены | K14: Цеховской В. | L14: планируется | M14: 3
A15: 2.4 | B15: Сменить учётные данные транков, AMI и базы данных | F15: ='Параметры и допущения'!$B$9+7 -> 46279 | G15: ='Параметры и допущения'!$B$9+11 -> 46283 | J15: Учётные данные сменены | K15: Цеховской В. | L15: планируется | M15: 2
A16: 2.5 | B16: Пересобрать конфигурации телефонов | F16: ='Параметры и допущения'!$B$9+7 -> 46279 | G16: ='Параметры и допущения'!$B$9+11 -> 46283 | J16: Телефоны работают с новыми паролями | K16: Цеховской В. | L16: планируется | M16: 1
A17: 2.6 | B17: Проверить восстановление из резервной копии на тестовой машине | F17: ='Параметры и допущения'!$B$9+7 -> 46279 | G17: ='Параметры и допущения'!$B$9+11 -> 46283 | J17: Копия развёрнута и проверена | K17: Цеховской В. | L17: планируется | M17: 1
A18: 3 | B18: Порядок оповещения техподдержки при отклонениях | C18: развитие | D18: Инфраструктура | E18: Савенко В. | F18: ='Параметры и допущения'!$B$9+7 -> 46279 | G18: ='Параметры и допущения'!$B$9+11 -> 46283 | H18: =G18 -> 46283 | I18: Работы идут на боевой телефонии, но не определено, кто поднимается по тревоге и что вообще считается отклонением — договариваться об этом после первой нештатной ситуации поздно | J18: Порядок согласован и роздан всем участникам работ: известны дежурный, канал связи, время реакции и перечень событий, по которым поднимают тревогу | K18: Цеховской В. | L18: планируется | M18: 2 | N18: ='Параметры и допущения'!$B$26*M18 -> 23030 | O18: 0
A19: 3.1 | B19: Определить перечень событий, по которым поднимают тревогу | F19: ='Параметры и допущения'!$B$9+7 -> 46279 | G19: ='Параметры и допущения'!$B$9+11 -> 46283 | J19: Зафиксированы: потеря регистраций на площадке, расхождение узлов кластера, недоступность панели управления, отказ транка в город | K19: Цеховской В. | L19: планируется | M19: 1
A20: 3.2 | B20: Назначить дежурного, канал связи и время реакции; раздать порядок | F20: ='Параметры и допущения'!$B$9+7 -> 46279 | G20: ='Параметры и допущения'!$B$9+11 -> 46283 | J20: У каждого участника работ есть памятка: кому, куда и за какое время сообщать | K20: Цеховской В. | L20: планируется | M20: 1
A21: 4 | B21: Испытательный стенд | C21: развитие | D21: Инфраструктура | E21: Савенко В. | F21: ='Параметры и допущения'!$B$9+14 -> 46286 | G21: ='Параметры и допущения'!$B$9+18 -> 46290 | H21: =G21 -> 46290 | I21: Процедуры восстановления кластера и передачи роли мастера ни разу не выполнялись | J21: Стенд из трёх машин прошёл чек-лист приёмки: клонирование, восстановление кворума и передача роли мастера выполнены руками | K21: Цеховской В. | L21: планируется | M21: 6 | N21: ='Параметры и допущения'!$B$26*M21 -> 69090 | O21: 0
A22: 4.1 | B22: Развернуть тестовый мастер и клонировать его в два узла | F22: ='Параметры и допущения'!$B$9+14 -> 46286 | G22: ='Параметры и допущения'!$B$9+18 -> 46290 | J22: Клоны вступили в кластер, конфликтов имён узлов нет | K22: Дулепов А. | L22: планируется | M22: 3
A23: 4.2 | B23: Отработать передачу роли мастера между двумя узлами | F23: ='Параметры и допущения'!$B$9+14 -> 46286 | G23: ='Параметры и допущения'!$B$9+18 -> 46290 | J23: Процедура выполнена в обе стороны и задокументирована | K23: Цеховской В. | L23: планируется | M23: 2
A24: 4.3 | B24: Отработать восстановление кворума | F24: ='Параметры и допущения'!$B$9+14 -> 46286 | G24: ='Параметры и допущения'!$B$9+18 -> 46290 | J24: Кворум восстановлен вручную | K24: Цеховской В. | L24: планируется | M24: 1
A25: 5 | B25: Ростовская АТС — первый узел кластера | C25: развитие | D25: Инфраструктура | E25: Савенко В. | F25: ='Параметры и допущения'!$B$9+21 -> 46293 | G25: ='Параметры и допущения'!$B$9+25 -> 46297 | H25: =G25 -> 46297 | I25: Вся боевая база живёт на ростовской АТС; перенести её в ЦОД без простоя можно только через кластер | J25: Ростовская АТС работает узлом кластера без переустановки; база готова к репликации в ЦОД | K25: Цеховской В. | L25: планируется | M25: 4 | N25: ='Параметры и допущения'!$B$26*M25 -> 46060 | O25: 0
A26: 5.1 | B26: Снять резервную копию, перевести таблицы и запустить репликацию | F26: ='Параметры и допущения'!$B$9+21 -> 46293 | G26: ='Параметры и допущения'!$B$9+25 -> 46297 | J26: База работает в режиме кластера, число добавочных сошлось | K26: Цеховской В. | L26: планируется | M26: 2
A27: 5.2 | B27: Выгрузить номера в общую базу и проверить | F27: ='Параметры и допущения'!$B$9+21 -> 46293 | G27: ='Параметры и допущения'!$B$9+25 -> 46297 | J27: Абоненты видны из общей базы | K27: Цеховской В. | L27: планируется | M27: 1
A28: 5.3 | B28: Наблюдение до переноса центра | F28: ='Параметры и допущения'!$B$9+21 -> 46293 | G28: ='Параметры и допущения'!$B$9+25 -> 46297 | J28: Отклонений не выявлено | K28: Цеховской В. | L28: планируется | M28: 1
A29: 6 | B29: Центр в московском ЦОД: два живых узла в разных залах | C29: развитие | D29: Инфраструктура | E29: Савенко В. | F29: ='Параметры и допущения'!$B$9+28 -> 46300 | G29: ='Параметры и допущения'!$B$9+39 -> 46311 | H29: =G29 -> 46311 | I29: Управление и база сосредоточены на ростовской АТС — площадке без резервирования; по решению совещания центр переносится в ЦОД с копией во втором зале | J29: Два живых узла в разных залах ЦОД обслуживают вызовы, управление на ЦОД-1; Ростов понижен до выноса, 80 московских абонентов поделены между залами | K29: Цеховской В. | L29: планируется | M29: 10 | N29: ='Параметры и допущения'!$B$26*M29 -> 115150 | O29: 0
A30: 6.1 | B30: Клонировать ростовскую АТС в ЦОД-1, расшить клон в узел | F30: ='Параметры и допущения'!$B$9+28 -> 46300 | G30: ='Параметры и допущения'!$B$9+32 -> 46304 | J30: ЦОД-1 в кластере, синхронизирован | K30: Дулепов А. | L30: планируется | M30: 2
A31: 6.2 | B31: Передать роль мастера с Ростова на ЦОД-1 | F31: ='Параметры и допущения'!$B$9+28 -> 46300 | G31: ='Параметры и допущения'!$B$9+32 -> 46304 | J31: FreePBX и управление работают из ЦОД-1 | K31: Цеховской В. | L31: планируется | M31: 2
A32: 6.3 | B32: Клонировать ЦОД-1 в ЦОД-2 (второй зал), расшить клон в узел | F32: ='Параметры и допущения'!$B$9+35 -> 46307 | G32: ='Параметры и допущения'!$B$9+39 -> 46311 | J32: ЦОД-2 в кластере, узлов три — кворум нечётный | K32: Дулепов А. | L32: планируется | M32: 2
A33: 6.4 | B33: Сделать ЦОД-2 живым узлом: транк оператора, FreePBX оставить выключенным | F33: ='Параметры и допущения'!$B$9+35 -> 46307 | G33: ='Параметры и допущения'!$B$9+39 -> 46311 | J33: ЦОД-2 несёт вызовы наравне с ЦОД-1; панель управления включена ровно на одном узле | K33: Цеховской В. | L33: планируется | M33: 2
A34: 6.5 | B34: Понизить Ростов до выноса, поделить 80 московских абонентов между залами | F34: ='Параметры и допущения'!$B$9+35 -> 46307 | G34: ='Параметры и допущения'!$B$9+39 -> 46311 | J34: По 40 абонентов на зал, каждый зал прописан другому резервным | K34: Цеховской В. | L34: планируется | M34: 2
A35: 7 | B35: Пилотный вынос — Ставрополь | C35: развитие | D35: Инфраструктура | E35: Савенко В. | F35: ='Параметры и допущения'!$B$9+42 -> 46314 | G35: ='Параметры и допущения'!$B$9+53 -> 46325 | H35: =G35 -> 46325 | I35: Схема «центр в ЦОД — вынос в городе» не проверена на реальной нагрузке и канале | J35: Ставрополь работает выносом: локальная регистрация телефонов, свой выход в город, переключение в ЦОД при отказе площадки; его 74 абонента больше не зависят от канала до Ростова | K35: Цеховской В. | L35: планируется | M35: 10 | N35: ='Параметры и допущения'!$B$26*M35 -> 115150 | O35: 0
A36: 7.1 | B36: Клонировать мастер и расшить клон в вынос | F36: ='Параметры и допущения'!$B$9+42 -> 46314 | G36: ='Параметры и допущения'!$B$9+46 -> 46318 | J36: Вынос в кластере | K36: Дулепов А. | L36: планируется | M36: 2
A37: 7.2 | B37: Настроить межузловые транки и перенести диалплан | F37: ='Параметры и допущения'!$B$9+42 -> 46314 | G37: ='Параметры и допущения'!$B$9+46 -> 46318 | J37: Вызовы между ЦОД, Ростовом и Ставрополем проходят | K37: Цеховской В. | L37: планируется | M37: 2
A38: 7.3 | B38: Подключить локальный транк оператора | F38: ='Параметры и допущения'!$B$9+42 -> 46314 | G38: ='Параметры и допущения'!$B$9+46 -> 46318 | J38: Свой выход в город работает | K38: Цеховской В. | L38: планируется | M38: 1
A39: 7.4 | B39: Перевести телефоны на вынос через провижининг | F39: ='Параметры и допущения'!$B$9+42 -> 46314 | G39: ='Параметры и допущения'!$B$9+46 -> 46318 | J39: Телефоны регистрируются в Ставрополе, резервный сервер — ЦОД-1 | K39: Цеховской В. | L39: планируется | M39: 2
A40: 7.5 | B40: Неделя наблюдения под реальной нагрузкой | F40: ='Параметры и допущения'!$B$9+49 -> 46321 | G40: ='Параметры и допущения'!$B$9+53 -> 46325 | J40: Отказ площадки и возврат отработаны, решение о тиражировании принято | K40: Цеховской В. | L40: планируется | M40: 3
...
